<?xml version="1.0" encoding="utf-8"?>
<!-- This URDF was automatically created by SolidWorks to URDF Exporter! Originally created by Stephen Brawner (brawner@gmail.com) 
     Commit Version: 1.6.0-4-g7f85cfe  Build Version: 1.6.7995.38578
     For more information, please see http://wiki.ros.org/sw_urdf_exporter -->
<robot name="taihu_revo2_description">

  <link name="base_link" />

  <link name="body_chassis">
    <inertial>
      <mass value="1.0"/>
      <origin xyz="0 0 0" rpy="0 0 0"/>
      <inertia ixx="0.01" iyy="0.01" izz="0.01" ixy="0.0" ixz="0.0" iyz="0.0"/>
    </inertial>
    <visual>
      <origin xyz="-0.1 0 -0.05" rpy="0 0 0" />
      <geometry>
        <box size="0.58 0.48 0.6"/>
      </geometry>
      <material name="">
        <color rgba="0.68 0.85 0.90 1.0" />
      </material>
    </visual>
    <collision>
      <origin xyz="-0.1 0 -0.05" rpy="0 0 0" />
      <geometry>
        <box size="0.58 0.48 0.6"/>
      </geometry>
    </collision>
  </link>
  <joint name="body_chassis_to_base" type="fixed">
    <origin xyz="0 0 0.3" rpy="0 0 0" />
    <parent link="base_link" />
    <child link="body_chassis" />
  </joint>

  <link name="waist_lift_link">
    <inertial>
      <mass value="1.0"/>
      <origin xyz="0 0 0" rpy="0 0 0"/>
      <inertia ixx="0.01" iyy="0.01" izz="0.01" ixy="0.0" ixz="0.0" iyz="0.0"/>
    </inertial>
    <visual>
      <origin xyz="0 0 0.229" rpy="0 0 0" />
      <geometry>
        <box size="0.2 0.36 0.458"/>
      </geometry>
      <material name="">
        <color rgba="0.68 0.85 0.90 1.0" />
      </material>
    </visual>
    <collision>
      <origin xyz="0 0 0.229" rpy="0 0 0" />
      <geometry>
        <box size="0.2 0.36 0.458"/>
      </geometry>
    </collision>
  </link>
  <joint name="waist_lift_joint" type="prismatic">
    <origin xyz="0.105 0 0" rpy="0 0 0" />
    <parent link="body_chassis" />
    <child link="waist_lift_link" />
    <axis xyz="0 0 1" />
    <limit lower="0" upper="0.25" effort="30" velocity="3.56" />
  </joint>

  <link name="waist_rotate_link">
    <inertial>
      <mass value="1.0"/>
      <origin xyz="0 0 0" rpy="0 0 0"/>
      <inertia ixx="0.01" iyy="0.01" izz="0.01" ixy="0.0" ixz="0.0" iyz="0.0"/>
    </inertial>
    <visual>
      <origin xyz="0 0 0.25" rpy="0 0 0" />
      <geometry>
        <box size="0.15 0.352 0.5"/>
      </geometry>
      <material name="">
        <color rgba="0.68 0.85 0.90 1.0" />
      </material>
    </visual>
    <collision>
      <origin xyz="0 0 0.25" rpy="0 0 0" />
      <geometry>
        <box size="0.15 0.352 0.5"/>
      </geometry>
    </collision>
  </link>
  <joint name="waist_rotate_joint" type="revolute">
    <origin xyz="0 0 0.458" rpy="0 0 0" />
    <parent link="waist_lift_link" />
    <child link="waist_rotate_link" />
    <axis xyz="0 -1 0" />
    <limit lower="-0.785" upper="0" effort="30" velocity="3.56" />
  </joint>

  <!-- ==========左臂========== -->
  <link name="L_SHOULDER_P_S">
    <inertial>
      <origin xyz="-0.0019399999999999999 0.057127000000000004 0.000195" rpy="0 0 0" />
      <mass value="0.9208189999999999" />
      <inertia ixx="0.0006496827709999999" ixy="1.4658272000000002e-05" ixz="5.451344e-06" iyy="0.000577163793" iyz="-2.58429e-07" izz="0.000774239006" />
    </inertial>
    <visual>
      <origin xyz="0 0 0" rpy="0 0 0" />
      <geometry>
        <mesh filename="package://taihu_dual_arm_description/meshes/taihu_dual_arm/L_SHOULDER_P_S.STL" />
      </geometry>
      <material name="">
        <color rgba="0.498039215686275 1 0.752941176470588 0.25" />
      </material>
    </visual>
    <collision>
      <origin xyz="0 0 0" rpy="0 0 0" />
      <geometry>
        <mesh filename="package://taihu_dual_arm_description/meshes/taihu_dual_arm/L_SHOULDER_P_S.STL" />
      </geometry>
    </collision>
  </link>
  <!-- 左臂1关节 -->
  <joint name="L_SHOULDER_P" type="revolute">
    <origin xyz="0 0.176 0.35" rpy="0 0 0" />
    <parent link="waist_rotate_link" />
    <child link="L_SHOULDER_P_S" />
    <axis xyz="0 1 0" />
    <limit lower="-3.14" upper="3.14" effort="30" velocity="3.56" />
  </joint>
  <link name="L_SHOULDER_R_S">
    <inertial>
      <origin xyz="-0.030573 0.093196 -1.3e-05" rpy="0 0 0" />
      <mass value="0.84539" />
      <inertia ixx="0.002428940148" ixy="8.3914874e-05" ixz="-4.27034e-07" iyy="0.0007977952330000001" iyz="-4.5671300000000005e-07" izz="0.002683768336" />
    </inertial>
    <visual>
      <origin xyz="0 0 0" rpy="0 0 0" />
      <geometry>
        <mesh filename="package://taihu_dual_arm_description/meshes/taihu_dual_arm/L_SHOULDER_R_S.STL" />
      </geometry>
      <material name="">
        <color rgba="0.890196078431372 0.890196078431372 0.913725490196078 1" />
      </material>
    </visual>
    <collision>
      <origin xyz="0 0 0" rpy="0 0 0" />
      <geometry>
        <mesh filename="package://taihu_dual_arm_description/meshes/taihu_dual_arm/L_SHOULDER_R_S.STL" />
      </geometry>
    </collision>
  </link>
  <!-- 左臂2关节 -->
  <joint name="L_SHOULDER_R" type="revolute">
    <origin xyz="0.0315 0.063 0" rpy="0 0 0" />
    <parent link="L_SHOULDER_P_S" />
    <child link="L_SHOULDER_R_S" />
    <axis xyz="1 0 0" />
    <limit lower="-1.5708" upper="0.5236" effort="30" velocity="3.56" />
  </joint>
  <link name="L_SHOULDER_Y_S">
    <inertial>
      <origin xyz="1.3e-05 0.091709 0.005607999999999999" rpy="0 0 0" />
      <mass value="0.737924" />
      <inertia ixx="0.0015841661110000001" ixy="-8.30242e-06" ixz="1.881447e-06" iyy="0.000376064881" iyz="-9.4524095e-05" izz="0.001557640898" />
    </inertial>
    <visual>
      <origin xyz="0 0 0" rpy="0 0 0" />
      <geometry>
        <mesh filename="package://taihu_dual_arm_description/meshes/taihu_dual_arm/L_SHOULDER_Y_S.STL" />
      </geometry>
      <material name="">
        <color rgba="0.890196078431372 0.890196078431372 0.913725490196078 1" />
      </material>
    </visual>
    <collision>
      <origin xyz="0 0 0" rpy="0 0 0" />
      <geometry>
        <mesh filename="package://taihu_dual_arm_description/meshes/taihu_dual_arm/L_SHOULDER_Y_S.STL" />
      </geometry>
    </collision>
  </link>
  <!-- 左臂3关节 -->
  <joint name="L_SHOULDER_Y" type="revolute">
    <origin xyz="-0.0315 0.1531 0" rpy="0 0 0" />
    <parent link="L_SHOULDER_R_S" />
    <child link="L_SHOULDER_Y_S" />
    <axis xyz="0 1 0" />
    <limit lower="-3.14" upper="3.14" effort="9.6" velocity="3.87" />
  </joint>
  <link name="L_ELBOW_Y_S">
    <inertial>
      <origin xyz="-0.000178 0.060241 -0.028396" rpy="0 0 0" />
      <mass value="0.52332" />
      <inertia ixx="0.000727710275" ixy="-2.7030279999999997e-06" ixz="-5.17084e-07" iyy="0.00037279695" iyz="2.7076888e-05" izz="0.000578764416" />
    </inertial>
    <visual>
      <origin xyz="0 0 0" rpy="0 0 0" />
      <geometry>
        <mesh filename="package://taihu_dual_arm_description/meshes/taihu_dual_arm/L_ELBOW_Y_S.STL" />
      </geometry>
      <material name="">
        <color rgba="0.372549019607843 0.529411764705882 1 1" />
      </material>
    </visual>
    <collision>
      <origin xyz="0 0 0" rpy="0 0 0" />
      <geometry>
        <mesh filename="package://taihu_dual_arm_description/meshes/taihu_dual_arm/L_ELBOW_Y_S.STL" />
      </geometry>
    </collision>
  </link>
  <!-- 左臂4关节 -->
  <joint name="L_ELBOW_Y" type="revolute">
    <origin xyz="0 0.1169 0.0296" rpy="0 0 0" />
    <parent link="L_SHOULDER_Y_S" />
    <child link="L_ELBOW_Y_S" />
    <axis xyz="0 0 1" />
    <limit lower="-1.83260" upper="0" effort="9.6" velocity="3.87" />
  </joint>
  <link name="L_WRIST_P_S">
    <inertial>
      <origin xyz="-8.999999999999999e-06 0.055689 0.021395" rpy="0 0 0" />
      <mass value="0.525106" />
      <inertia ixx="0.001192088817" ixy="-4.4416e-08" ixz="-2.11547e-07" iyy="0.000351510751" iyz="-0.000193463174" izz="0.00109415209" />
    </inertial>
    <visual>
      <origin xyz="0 0 0" rpy="0 0 0" />
      <geometry>
        <mesh filename="package://taihu_dual_arm_description/meshes/taihu_dual_arm/L_WRIST_P_S.STL" />
      </geometry>
      <material name="">
        <color rgba="0.890196078431372 0.890196078431372 0.913725490196078 1" />
      </material>
    </visual>
    <collision>
      <origin xyz="0 0 0" rpy="0 0 0" />
      <geometry>
        <mesh filename="package://taihu_dual_arm_description/meshes/taihu_dual_arm/L_WRIST_P_S.STL" />
      </geometry>
    </collision>
  </link>
  <!-- 左臂5关节 -->
  <joint name="L_WRIST_P" type="revolute">
    <origin xyz="0 0.105 -0.0296" rpy="0 0 0" />
    <parent link="L_ELBOW_Y_S" />
    <child link="L_WRIST_P_S" />
    <axis xyz="0 1 0" />
    <limit lower="-3.14" upper="3.14" effort="6.5" velocity="4.19" />
  </joint>
  <link name="L_WRIST_Y_S">
    <inertial>
      <origin xyz="0.0059889999999999995 -0.000149 -0.034146" rpy="0 0 0" />
      <mass value="0.212671" />
      <inertia ixx="2.622574e-05" ixy="-1.051362e-06" ixz="-2.62024e-07" iyy="5.2490884e-05" iyz="-9.7555e-08" izz="4.3769675999999996e-05" />
    </inertial>
    <visual>
      <origin xyz="0 0 0" rpy="0 0 0" />
      <geometry>
        <mesh filename="package://taihu_dual_arm_description/meshes/taihu_dual_arm/L_WRIST_Y_S.STL" />
      </geometry>
      <material name="">
        <color rgba="0.898039215686275 0.917647058823529 0.929411764705882 1" />
      </material>
    </visual>
    <collision>
      <origin xyz="0 0 0" rpy="0 0 0" />
      <geometry>
        <mesh filename="package://taihu_dual_arm_description/meshes/taihu_dual_arm/L_WRIST_Y_S.STL" />
      </geometry>
    </collision>
  </link>
  <!-- 左臂6关节 -->
  <joint name="L_WRIST_Y" type="revolute">
    <origin xyz="0 0.145 0.036" rpy="0 0 0" />
    <parent link="L_WRIST_P_S" />
    <child link="L_WRIST_Y_S" />
    <axis xyz="0 0 1" />
    <limit lower="-1.3963" upper="1.3963" effort="2.8" velocity="4.71" />
  </joint>
  <link name="L_WRIST_R_S">
    <inertial>
      <origin xyz="-0.022931999999999998 0.048783 0.0" rpy="0 0 0" />
      <mass value="0.11904300000000001" />
      <inertia ixx="0.000140085173" ixy="1.5388019e-05" ixz="-3.72e-10" iyy="0.000113287347" iyz="2e-12" izz="0.000213565666" />
    </inertial>
    <visual>
      <origin xyz="0 0 0" rpy="0 0 0" />
      <geometry>
        <mesh filename="package://taihu_dual_arm_description/meshes/taihu_dual_arm/L_WRIST_R_S.STL" />
      </geometry>
      <material name="">
        <color rgba="0.776470588235294 0.756862745098039 0.737254901960784 1" />
      </material>
    </visual>
    <collision>
      <origin xyz="0 0 0" rpy="0 0 0" />
      <geometry>
        <mesh filename="package://taihu_dual_arm_description/meshes/taihu_dual_arm/L_WRIST_R_S.STL" />
      </geometry>
    </collision>
  </link>
  <!-- 左臂7关节 -->
  <joint name="L_WRIST_R" type="revolute">
    <origin xyz="0.026 0 -0.036" rpy="0 0 0" />
    <parent link="L_WRIST_Y_S" />
    <child link="L_WRIST_R_S" />
    <axis xyz="1 0 0" />
    <limit lower="-1.5533" upper="0.8726" effort="2.8" velocity="4.71" />
  </joint>
  <!-- 左臂末端 link -->
  <link name="L_HAND_S">
    <inertial>
      <origin xyz="0.0 -0.016413 0.0" rpy="0 0 0" />
      <mass value="0.043451000000000004" />
      <inertia ixx="1.7165183e-05" ixy="-0.0" ixz="-0.0" iyy="2.7695936000000002e-05" iyz="-0.0" izz="1.7165183e-05" />
    </inertial>
    <visual>
      <origin xyz="0 0 0" rpy="0 0 0" />
      <geometry>
        <mesh filename="package://taihu_dual_arm_description/meshes/taihu_dual_arm/L_HAND_S.STL" />
      </geometry>
      <material name="">
        <color rgba="0.776470588235294 0.756862745098039 0.737254901960784 1" />
      </material>
    </visual>
    <collision>
      <origin xyz="0 0 0" rpy="0 0 0" />
      <geometry>
        <mesh filename="package://taihu_dual_arm_description/meshes/taihu_dual_arm/L_HAND_S.STL" />
      </geometry>
    </collision>
  </link>
  <joint name="L_HAND" type="fixed">
    <!-- 末端法兰 -->
    <origin xyz="-0.026 0.096 0" rpy="0 0 0" />
    <parent link="L_WRIST_R_S" />
    <child link="L_HAND_S" />
    <axis xyz="0 0 0" />
  </joint>

  <link name="left_tool_link"/>
  <joint name="left_tool_joint" type="fixed">
    <!-- 末端法兰 -->
    <!-- <origin xyz="0 0 0" rpy="0 0 0" /> -->
    <!-- 末端link延长 -->
    <origin xyz="0 0.15 0" rpy="0 0 0" />
    <parent link="L_HAND_S" />
    <child link="left_tool_link" />
    <axis xyz="0 0 0" />
  </joint>


  <!-- ==========右臂========== -->
  <link name="R_SHOULDER_P_S">
    <inertial>
      <origin xyz="-0.0019399999999999999 -0.057112 0.000192" rpy="0 0 0" />
      <mass value="0.920818" />
      <inertia ixx="0.0006495133669999999" ixy="-1.4207998999999999e-05" ixz="5.379159e-06" iyy="0.0005774215999999999" iyz="1.1307159999999998e-06" izz="0.000773812316" />
    </inertial>
    <visual>
      <origin xyz="0 0 0" rpy="0 0 0" />
      <geometry>
        <mesh filename="package://taihu_dual_arm_description/meshes/taihu_dual_arm/R_SHOULDER_P_S.STL" />
      </geometry>
      <material name="">
        <color rgba="0.498039215686275 1 0.752941176470588 0.25" />
      </material>
    </visual>
    <collision>
      <origin xyz="0 0 0" rpy="0 0 0" />
      <geometry>
        <mesh filename="package://taihu_dual_arm_description/meshes/taihu_dual_arm/R_SHOULDER_P_S.STL" />
      </geometry>
    </collision>
  </link>
  <!-- 右臂1关节 -->
  <joint name="R_SHOULDER_P" type="revolute">
    <origin xyz="0 -0.176 0.35" rpy="0 0 0" />
    <parent link="waist_rotate_link" />
    <child link="R_SHOULDER_P_S" />
    <axis xyz="0 -1 0" />
    <limit lower="-3.14" upper="3.14" effort="30" velocity="3.56" />
  </joint>
  <link name="R_SHOULDER_R_S">
    <inertial>
      <origin xyz="-0.030572 -0.09319799999999999 -1.4e-05" rpy="0 0 0" />
      <mass value="0.845406" />
      <inertia ixx="0.002428519898" ixy="-8.4092152e-05" ixz="-4.27706e-07" iyy="0.000797828856" iyz="4.6162200000000003e-07" izz="0.002683361853" />
    </inertial>
    <visual>
      <origin xyz="0 0 0" rpy="0 0 0" />
      <geometry>
        <mesh filename="package://taihu_dual_arm_description/meshes/taihu_dual_arm/R_SHOULDER_R_S.STL" />
      </geometry>
      <material name="">
        <color rgba="0.890196078431372 0.890196078431372 0.913725490196078 1" />
      </material>
    </visual>
    <collision>
      <origin xyz="0 0 0" rpy="0 0 0" />
      <geometry>
        <mesh filename="package://taihu_dual_arm_description/meshes/taihu_dual_arm/R_SHOULDER_R_S.STL" />
      </geometry>
    </collision>
  </link>
  <!-- 右臂2关节 -->
  <joint name="R_SHOULDER_R" type="revolute">
    <origin xyz="0.0315 -0.063 0" rpy="0 0 0" />
    <parent link="R_SHOULDER_P_S" />
    <child link="R_SHOULDER_R_S" />
    <axis xyz="1 0 0" />
    <limit lower="-0.5236" upper="1.5708" effort="30" velocity="3.56" />
  </joint>
  <link name="R_SHOULDER_Y_S">
    <inertial>
      <origin xyz="1.4999999999999999e-05 -0.091477 0.005607999999999999" rpy="0 0 0" />
      <mass value="0.7379220000000001" />
      <inertia ixx="0.0015754626029999999" ixy="7.884843e-06" ixz="1.936734e-06" iyy="0.000376073783" iyz="0.000100049969" izz="0.001548948128" />
    </inertial>
    <visual>
      <origin xyz="0 0 0" rpy="0 0 0" />
      <geometry>
        <mesh filename="package://taihu_dual_arm_description/meshes/taihu_dual_arm/R_SHOULDER_Y_S.STL" />
      </geometry>
      <material name="">
        <color rgba="0.890196078431372 0.890196078431372 0.913725490196078 1" />
      </material>
    </visual>
    <collision>
      <origin xyz="0 0 0" rpy="0 0 0" />
      <geometry>
        <mesh filename="package://taihu_dual_arm_description/meshes/taihu_dual_arm/R_SHOULDER_Y_S.STL" />
      </geometry>
    </collision>
  </link>
  <!-- 右臂3关节 -->
  <joint name="R_SHOULDER_Y" type="revolute">
    <origin xyz="-0.0315 -0.1531 0" rpy="0 0 0" />
    <parent link="R_SHOULDER_R_S" />
    <child link="R_SHOULDER_Y_S" />
    <axis xyz="0 -1 0" />
    <limit lower="-3.14" upper="3.14" effort="9.6" velocity="3.87" />
  </joint>
  <link name="R_ELBOW_Y_S">
    <inertial>
      <origin xyz="-0.00017999999999999998 -0.06024 -0.028398" rpy="0 0 0" />
      <mass value="0.523365" />
      <inertia ixx="0.000727623074" ixy="2.767832e-06" ixz="-4.74173e-07" iyy="0.000372871841" iyz="-2.7159758000000002e-05" izz="0.000578634305" />
    </inertial>
    <visual>
      <origin xyz="0 0 0" rpy="0 0 0" />
      <geometry>
        <mesh filename="package://taihu_dual_arm_description/meshes/taihu_dual_arm/R_ELBOW_Y_S.STL" />
      </geometry>
      <material name="">
        <color rgba="0.372549019607843 0.529411764705882 1 1" />
      </material>
    </visual>
    <collision>
      <origin xyz="0 0 0" rpy="0 0 0" />
      <geometry>
        <mesh filename="package://taihu_dual_arm_description/meshes/taihu_dual_arm/R_ELBOW_Y_S.STL" />
      </geometry>
    </collision>
  </link>
  <!-- 右臂4关节 -->
  <joint name="R_ELBOW_Y" type="revolute">
    <origin xyz="0 -0.1169 0.0296" rpy="0 0 0" />
    <parent link="R_SHOULDER_Y_S" />
    <child link="R_ELBOW_Y_S" />
    <axis xyz="0 0 1" />
    <limit lower="0" upper="1.83260" effort="9.6" velocity="3.87" />
  </joint>
  <link name="R_WRIST_P_S">
    <inertial>
      <origin xyz="-1.2e-05 -0.055816000000000004 0.021369" rpy="0 0 0" />
      <mass value="0.525101" />
      <inertia ixx="0.00118952494" ixy="1.86748e-07" ixz="-1.1971299999999998e-07" iyy="0.000351377546" iyz="0.00019070709299999998" izz="0.001091710961" />
    </inertial>
    <visual>
      <origin xyz="0 0 0" rpy="0 0 0" />
      <geometry>
        <mesh filename="package://taihu_dual_arm_description/meshes/taihu_dual_arm/R_WRIST_P_S.STL" />
      </geometry>
      <material name="">
        <color rgba="0.890196078431372 0.890196078431372 0.913725490196078 1" />
      </material>
    </visual>
    <collision>
      <origin xyz="0 0 0" rpy="0 0 0" />
      <geometry>
        <mesh filename="package://taihu_dual_arm_description/meshes/taihu_dual_arm/R_WRIST_P_S.STL" />
      </geometry>
    </collision>
  </link>
  <!-- 右臂5关节 -->
  <joint name="R_WRIST_P" type="revolute">
    <origin xyz="0 -0.105 -0.0296" rpy="0 0 0" />
    <parent link="R_ELBOW_Y_S" />
    <child link="R_WRIST_P_S" />
    <axis xyz="0 -1 0" />
    <limit lower="-3.14" upper="3.14" effort="6.5" velocity="4.19" />
  </joint>
  <link name="R_WRIST_Y_S">
    <inertial>
      <origin xyz="0.0059889999999999995 0.00016 -0.034092" rpy="0 0 0" />
      <mass value="0.212671" />
      <inertia ixx="2.6182065e-05" ixy="1.129275e-06" ixz="1.3503e-07" iyy="5.2412779e-05" iyz="1.7324999999999998e-08" izz="4.3804106e-05" />
    </inertial>
    <visual>
      <origin xyz="0 0 0" rpy="0 0 0" />
      <geometry>
        <mesh filename="package://taihu_dual_arm_description/meshes/taihu_dual_arm/R_WRIST_Y_S.STL" />
      </geometry>
      <material name="">
        <color rgba="0.898039215686275 0.917647058823529 0.929411764705882 1" />
      </material>
    </visual>
    <collision>
      <origin xyz="0 0 0" rpy="0 0 0" />
      <geometry>
        <mesh filename="package://taihu_dual_arm_description/meshes/taihu_dual_arm/R_WRIST_Y_S.STL" />
      </geometry>
    </collision>
  </link>
  <!-- 右臂6关节 -->
  <joint name="R_WRIST_Y" type="revolute">
    <origin xyz="0 -0.145 0.036" rpy="0 0 0" />
    <parent link="R_WRIST_P_S" />
    <child link="R_WRIST_Y_S" />
    <axis xyz="0 0 1" />
    <limit lower="-1.3963" upper="1.3963" effort="2.8" velocity="4.71" />
  </joint>
  <link name="R_WRIST_R_S">
    <inertial>
      <origin xyz="-0.022931999999999998 -0.048783 -1e-06" rpy="0 0 0" />
      <mass value="0.11904300000000001" />
      <inertia ixx="0.00014008507199999998" ixy="-1.538806e-05" ixz="-3.568e-09" iyy="0.000113287372" iyz="5.9260000000000004e-09" izz="0.00021356554000000002" />
    </inertial>
    <visual>
      <origin xyz="0 0 0" rpy="0 0 0" />
      <geometry>
        <mesh filename="package://taihu_dual_arm_description/meshes/taihu_dual_arm/R_WRIST_R_S.STL" />
      </geometry>
      <material name="">
        <color rgba="0.776470588235294 0.756862745098039 0.737254901960784 1" />
      </material>
    </visual>
    <collision>
      <origin xyz="0 0 0" rpy="0 0 0" />
      <geometry>
        <mesh filename="package://taihu_dual_arm_description/meshes/taihu_dual_arm/R_WRIST_R_S.STL" />
      </geometry>
    </collision>
  </link>
  <!-- 右臂7关节 -->
  <joint name="R_WRIST_R" type="revolute">
    <origin xyz="0.026 0 -0.036" rpy="0 0 0" />
    <parent link="R_WRIST_Y_S" />
    <child link="R_WRIST_R_S" />
    <axis xyz="1 0 0" />
    <limit lower="-0.8726" upper="1.5533" effort="2.8" velocity="4.71" />
  </joint>
  <!-- 右臂末端 link -->
  <link name="R_HAND_S">
    <inertial>
      <origin xyz="0.0 0.016413 0.0" rpy="0 0 0" />
      <mass value="0.043451000000000004" />
      <inertia ixx="1.7165183e-05" ixy="-0.0" ixz="-0.0" iyy="2.7695936000000002e-05" iyz="-0.0" izz="1.7165183e-05" />
    </inertial>
    <visual>
      <origin xyz="0 0 0" rpy="0 0 0" />
      <geometry>
        <mesh filename="package://taihu_dual_arm_description/meshes/taihu_dual_arm/R_HAND_S.STL" />
      </geometry>
      <material name="">
        <color rgba="0.776470588235294 0.756862745098039 0.737254901960784 1" />
      </material>
    </visual>
    <collision>
      <origin xyz="0 0 0" rpy="0 0 0" />
      <geometry>
        <mesh filename="package://taihu_dual_arm_description/meshes/taihu_dual_arm/R_HAND_S.STL" />
      </geometry>
    </collision>
  </link>
  <joint name="R_HAND" type="fixed">
    <!-- 末端法兰 -->
    <origin xyz="-0.026 -0.096 0" rpy="0 0 0" />
    <parent link="R_WRIST_R_S" />
    <child link="R_HAND_S" />
    <axis xyz="0 0 0" />
  </joint>

  <link name="right_tool_link"/>
  <joint name="right_tool_joint" type="fixed">
    <!-- 末端法兰 -->
    <!-- <origin xyz="0 0 0" rpy="0 0 0" /> -->
    <!-- 末端link延长 -->
    <origin xyz="0 -0.15 0" rpy="0 0 0" />
    <parent link="R_HAND_S" />
    <child link="right_tool_link" />
    <axis xyz="0 0 0" />
  </joint>

  <!-- left hand -->
  <link name="left_hand_base_link">
    <inertial>
      <origin xyz="-0.00526250771717109 0.00339255905687133 0.0521379173026012" rpy="0 0 0" />
      <mass value="0.238" />
      <inertia ixx="2.10902217235295E-05" ixy="-3.91382468722039E-08" ixz="9.20954665152033E-08" iyy="1.44592446991944E-05" iyz="1.10000625250951E-06" izz="7.99782051792634E-06" />
    </inertial>
    <visual>
      <origin xyz="0 0 0" rpy="0 0 0" />
      <geometry>
        <mesh filename="package://taihu_dual_arm_description/meshes/revo2_left_hand/left_base_link.STL" />
      </geometry>
      <material name="">
        <color rgba="1 1 1 1" />
      </material>
    </visual>
    <visual>
      <origin xyz="0 0 0" rpy="0 0 0" />
      <geometry>
        <mesh filename="package://taihu_dual_arm_description/meshes/revo2_left_hand/left_base_visual_link.STL" />
      </geometry>
      <material name="">
        <color rgba="1 1 1 1" />
      </material>
    </visual>
    <collision>
      <origin xyz="0 0 0" rpy="0 0 0" />
      <geometry>
        <mesh filename="package://taihu_dual_arm_description/meshes/revo2_left_hand/left_base_link.STL" />
      </geometry>
    </collision>
  </link>
  <joint name="left_hand_base_joint" type="fixed">
    <origin xyz="0 0 0" rpy="-1.5707963 1.5707963 0" />
    <parent link="L_HAND_S" />
    <child link="left_hand_base_link" />
    <axis xyz="0 0 0" />
  </joint>
  <link name="left_thumb_metacarpal_link">
    <inertial>
      <origin xyz="1.52303696287076E-05 -0.00707240283482268 -0.00420839832903629" rpy="0 0 0" />
      <mass value="0.01" />
      <inertia ixx="1.59238866130872E-07" ixy="4.69114607598503E-09" ixz="4.93233725002151E-10" iyy="1.60911967461756E-07" iyz="1.48144948560702E-08" izz="5.13544258620214E-08" />
    </inertial>
    <visual>
      <origin xyz="0 0 0" rpy="0 0 0" />
      <geometry>
        <mesh filename="package://taihu_dual_arm_description/meshes/revo2_left_hand/left_thumb_metacarpal_link.STL" />
      </geometry>
      <material name="">
        <color rgba="1 1 1 1" />
      </material>
    </visual>
    <collision>
      <origin xyz="0 0 0" rpy="0 0 0" />
      <geometry>
        <mesh filename="package://taihu_dual_arm_description/meshes/revo2_left_hand/left_thumb_metacarpal_link.STL" />
      </geometry>
    </collision>
  </link>
  <joint name="left_thumb_metacarpal_joint" type="revolute">
    <origin xyz="0.0045 -0.019 0.027825" rpy="0 0 0.16787" />
    <parent link="left_hand_base_link" />
    <child link="left_thumb_metacarpal_link" />
    <axis xyz="0 0 1" />
    <limit lower="0" upper="1.57" effort="0.5" velocity="2.6175" />
  </joint>
  <link name="left_thumb_proximal_link">
    <inertial>
      <origin xyz="-3.69149416382109E-07 -0.0277015790929176 -0.00202668257181579" rpy="0 0 0" />
      <mass value="0.05" />
      <inertia ixx="2.40450829263392E-06" ixy="1.70278763843824E-10" ixz="1.21632944893438E-11" iyy="5.12299191364743E-07" iyz="2.89023502749285E-08" izz="2.56255682995404E-06" />
    </inertial>
    <visual>
      <origin xyz="0 0 0" rpy="0 0 0" />
      <geometry>
        <mesh filename="package://taihu_dual_arm_description/meshes/revo2_left_hand/left_thumb_proximal_link.STL" />
      </geometry>
      <material name="">
        <color rgba="1 1 1 1" />
      </material>
    </visual>
    <visual>
      <origin xyz="0 0 0" rpy="0 0 0" />
      <geometry>
        <mesh filename="package://taihu_dual_arm_description/meshes/revo2_left_hand/left_thumb_proximal_visual_link.STL" />
      </geometry>
      <material name="">
        <color rgba="1 1 1 1" />
      </material>
    </visual>
    <collision>
      <origin xyz="0 0 0" rpy="0 0 0" />
      <geometry>
        <mesh filename="package://taihu_dual_arm_description/meshes/revo2_left_hand/left_thumb_proximal_link.STL" />
      </geometry>
    </collision>
  </link>
  <joint name="left_thumb_proximal_joint" type="revolute">
    <origin xyz="0 -0.014227 0" rpy="-0.17488 0.23736 -0.16787" />
    <parent link="left_thumb_metacarpal_link" />
    <child link="left_thumb_proximal_link" />
    <axis xyz="-1 0 0" />
    <limit lower="0" upper="1.03" effort="1.1" velocity="2.5303" />
  </joint>
  <link name="left_thumb_distal_link">
    <inertial>
      <origin xyz="1.65618684180163E-07 -0.0117550891981016 1.1366609064185E-05" rpy="0 0 0" />
      <mass value="0.01" />
      <inertia ixx="1.6780928553031E-07" ixy="1.91856562375217E-11" ixz="2.69475202672276E-12" iyy="1.15357239984326E-07" iyz="-1.25182560702847E-08" izz="2.1956615213811E-07" />
    </inertial>
    <visual>
      <origin xyz="0 0 0" rpy="0 0 0" />
      <geometry>
        <mesh filename="package://taihu_dual_arm_description/meshes/revo2_left_hand/left_thumb_distal_link.STL" />
      </geometry>
      <material name="">
        <color rgba="1 1 1 1" />
      </material>
    </visual>
    <collision>
      <origin xyz="0 0 0" rpy="0 0 0" />
      <geometry>
        <mesh filename="package://taihu_dual_arm_description/meshes/revo2_left_hand/left_thumb_distal_link.STL" />
      </geometry>
    </collision>
  </link>
  <joint name="left_thumb_distal_joint" type="revolute">
    <origin xyz="0 -0.052 0" rpy="0 0 0" />
    <parent link="left_thumb_proximal_link" />
    <child link="left_thumb_distal_link" />
    <axis xyz="-1 0 0" />
    <limit lower="0" upper="1.03" effort="1.1" velocity="2.5303" />
    <mimic joint="left_thumb_proximal_joint" multiplier="1" offset="0" />
  </joint>
  <link name="left_thumb_tip_link">
  </link>
  <joint name="left_thumb_tip_joint" type="fixed">
    <origin xyz="0 -0.026529 -0.0017734" rpy="0.06675 0 0" />
    <parent link="left_thumb_distal_link" />
    <child link="left_thumb_tip_link" />
    <axis xyz="0 0 0" />
  </joint>
  <link name="left_thumb_touch_link">
    <inertial>
      <origin xyz="1.3569875392111E-07 0.000717207158422314 -0.00790252458933401" rpy="0 0 0" />
      <mass value="0.002" />
      <inertia ixx="1.67809287404785E-07" ixy="1.93619566820214E-11" ixz="-6.84472317111877E-13" iyy="1.14222234138764E-07" iyz="6.09432087624352E-09" izz="2.20701159969439E-07" />
    </inertial>
    <visual>
      <origin xyz="0 0 0" rpy="0 0 0" />
      <geometry>
        <mesh filename="package://taihu_dual_arm_description/meshes/revo2_left_hand/left_thumb_touch_link.STL" />
      </geometry>
      <material name="">
        <color rgba="1 1 1 1" />
      </material>
    </visual>
    <collision>
      <origin xyz="0 0 0" rpy="0 0 0" />
      <geometry>
        <mesh filename="package://taihu_dual_arm_description/meshes/revo2_left_hand/left_thumb_touch_link.STL" />
      </geometry>
    </collision>
  </link>
  <joint name="left_thumb_touch_joint" type="fixed">
    <origin xyz="0 -0.013836 0.0076686" rpy="0.17488 0 0" />
    <parent link="left_thumb_distal_link" />
    <child link="left_thumb_touch_link" />
    <axis xyz="0 0 0" />
  </joint>
  <link name="left_index_proximal_link">
    <inertial>
      <origin xyz="-0.002235387426012 -3.80544615179342E-06 0.0176439423080373" rpy="0 0 0" />
      <mass value="0.009" />
      <inertia ixx="2.51863526940901E-07" ixy="-3.10934654014342E-11" ixz="-6.36901300651623E-09" iyy="2.36343210839019E-07" iyz="-1.71663811116803E-10" izz="9.30397543724724E-08" />
    </inertial>
    <visual>
      <origin xyz="0 0 0" rpy="0 0 0" />
      <geometry>
        <mesh filename="package://taihu_dual_arm_description/meshes/revo2_left_hand/left_index_proximal_link.STL" />
      </geometry>
      <material name="">
        <color rgba="1 1 1 1" />
      </material>
    </visual>
    <collision>
      <origin xyz="0 0 0" rpy="0 0 0" />
      <geometry>
        <mesh filename="package://taihu_dual_arm_description/meshes/revo2_left_hand/left_index_proximal_link.STL" />
      </geometry>
    </collision>
  </link>
  <joint name="left_index_proximal_joint" type="revolute">
    <origin xyz="-0.0021349 -0.029578 0.080876" rpy="0.11819 0.14743 0.17422" />
    <parent link="left_hand_base_link" />
    <child link="left_index_proximal_link" />
    <axis xyz="0 1 0" />
    <limit lower="0" upper="1.41" effort="2" velocity="2.2685" />
  </joint>
  <link name="left_index_distal_link">
    <inertial>
      <origin xyz="0.00330165933067644 6.31887000952791E-08 0.0142075801783598" rpy="0 0 0" />
      <mass value="0.009" />
      <inertia ixx="3.39958467120803E-07" ixy="-2.00727556234471E-14" ixz="-8.7500943582372E-08" iyy="3.62235423626446E-07" iyz="2.21291910181288E-12" izz="9.10339055645575E-08" />
    </inertial>
    <visual>
      <origin xyz="0 0 0" rpy="0 0 0" />
      <geometry>
        <mesh filename="package://taihu_dual_arm_description/meshes/revo2_left_hand/left_index_distal_link.STL" />
      </geometry>
      <material name="">
        <color rgba="1 1 1 1" />
      </material>
    </visual>
    <collision>
      <origin xyz="0 0 0" rpy="0 0 0" />
      <geometry>
        <mesh filename="package://taihu_dual_arm_description/meshes/revo2_left_hand/left_index_distal_link.STL" />
      </geometry>
    </collision>
  </link>
  <joint name="left_index_distal_joint" type="revolute">
    <origin xyz="0 0 0.032" rpy="0 0 0" />
    <parent link="left_index_proximal_link" />
    <child link="left_index_distal_link" />
    <axis xyz="0 1 0" />
    <limit lower="0" upper="1.63" effort="2" velocity="2.2685" />
    <mimic joint="left_index_proximal_joint" multiplier="1.155" offset="0" />
  </joint>
  <link name="left_index_tip_link">
  </link>
  <joint name="left_index_tip_joint" type="fixed">
    <origin xyz="0.011097 0 0.035739" rpy="0 0.48723 0" />
    <parent link="left_index_distal_link" />
    <child link="left_index_tip_link" />
    <axis xyz="0 0 0" />
  </joint>
  <link name="left_index_touch_link">
    <inertial>
      <origin xyz="-0.00299918181799204 7.01974568750874E-09 0.00252369841562855" rpy="0 0 0" />
      <mass value="0.002" />
      <inertia ixx="6.77729843516625E-09" ixy="1.88703692893536E-14" ixz="1.51511606529797E-09" iyy="5.41485427527447E-09" iyz="7.54610125535653E-13" izz="3.19157470008512E-09" />
    </inertial>
    <visual>
      <origin xyz="0 0 0" rpy="0 0 0" />
      <geometry>
        <mesh filename="package://taihu_dual_arm_description/meshes/revo2_left_hand/left_index_touch_link.STL" />
      </geometry>
      <material name="">
        <color rgba="1 1 1 1" />
      </material>
    </visual>
    <collision>
      <origin xyz="0 0 0" rpy="0 0 0" />
      <geometry>
        <mesh filename="package://taihu_dual_arm_description/meshes/revo2_left_hand/left_index_touch_link.STL" />
      </geometry>
    </collision>
  </link>
  <joint name="left_index_touch_joint" type="fixed">
    <origin xyz="0.014497 0 0.023303" rpy="0 0.4756 0" />
    <parent link="left_index_distal_link" />
    <child link="left_index_touch_link" />
    <axis xyz="0 0 0" />
  </joint>
  <link name="left_middle_proximal_link">
    <inertial>
      <origin xyz="-0.00222419445309931 -3.61990820813788E-06 0.0203049526045434" rpy="0 0 0" />
      <mass value="0.009" />
      <inertia ixx="3.66885320718611E-07" ixy="-3.6430334370348E-11" ixz="-9.77995332041373E-09" iyy="3.5252138716754E-07" iyz="-2.58098211906242E-10" izz="1.12242284171831E-07" />
    </inertial>
    <visual>
      <origin xyz="0 0 0" rpy="0 0 0" />
      <geometry>
        <mesh filename="package://taihu_dual_arm_description/meshes/revo2_left_hand/left_middle_proximal_link.STL" />
      </geometry>
      <material name="">
        <color rgba="1 1 1 1" />
      </material>
    </visual>
    <collision>
      <origin xyz="0 0 0" rpy="0 0 0" />
      <geometry>
        <mesh filename="package://taihu_dual_arm_description/meshes/revo2_left_hand/left_middle_proximal_link.STL" />
      </geometry>
    </collision>
  </link>
  <joint name="left_middle_proximal_joint" type="revolute">
    <origin xyz="-0.0045935 -0.010061 0.084993" rpy="0.039468 0.1483 0.057975" />
    <parent link="left_hand_base_link" />
    <child link="left_middle_proximal_link" />
    <axis xyz="0 1 0" />
    <limit lower="0" upper="1.41" effort="2" velocity="2.2685" />
  </joint>
  <link name="left_middle_distal_link">
    <inertial>
      <origin xyz="0.00189418007863382 -2.26465967662765E-08 0.0168711148865022" rpy="0 0 0" />
      <mass value="0.009" />
      <inertia ixx="5.40534108976802E-07" ixy="2.94130244214777E-12" ixz="-8.35162930404456E-08" iyy="5.49812279010797E-07" iyz="7.84699400870312E-13" izz="9.55606707448008E-08" />
    </inertial>
    <visual>
      <origin xyz="0 0 0" rpy="0 0 0" />
      <geometry>
        <mesh filename="package://taihu_dual_arm_description/meshes/revo2_left_hand/left_middle_distal_link.STL" />
      </geometry>
      <material name="">
        <color rgba="1 1 1 1" />
      </material>
    </visual>
    <collision>
      <origin xyz="0 0 0" rpy="0 0 0" />
      <geometry>
        <mesh filename="package://taihu_dual_arm_description/meshes/revo2_left_hand/left_middle_distal_link.STL" />
      </geometry>
    </collision>
  </link>
  <joint name="left_middle_distal_joint" type="revolute">
    <origin xyz="0 0 0.037" rpy="0 0.12654 0" />
    <parent link="left_middle_proximal_link" />
    <child link="left_middle_distal_link" />
    <axis xyz="0 1 0" />
    <limit lower="0" upper="1.63" effort="2" velocity="2.2685" />
    <mimic joint="left_middle_proximal_joint" multiplier="1.155" offset="0" />
  </joint>
  <link name="left_middle_tip_link">
  </link>
  <joint name="left_middle_tip_joint" type="fixed">
    <origin xyz="0.0073534 0 0.041703" rpy="0 0.34907 0" />
    <parent link="left_middle_distal_link" />
    <child link="left_middle_tip_link" />
    <axis xyz="0 0 0" />
  </joint>
  <link name="left_middle_touch_link">
    <inertial>
      <origin xyz="-0.00319288866167638 -2.94334979245373E-08 0.00297859877777221" rpy="0 0 0" />
      <mass value="0.002" />
      <inertia ixx="1.00486919311226E-08" ixy="-5.43894280644511E-14" ixz="2.25918051958301E-09" iyy="8.23231100847473E-09" iyz="1.97875022250685E-13" izz="4.41272539147384E-09" />
    </inertial>
    <visual>
      <origin xyz="0 0 0" rpy="0 0 0" />
      <geometry>
        <mesh filename="package://taihu_dual_arm_description/meshes/revo2_left_hand/left_middle_touch_link.STL" />
      </geometry>
      <material name="">
        <color rgba="1 1 1 1" />
      </material>
    </visual>
    <collision>
      <origin xyz="0 0 0" rpy="0 0 0" />
      <geometry>
        <mesh filename="package://taihu_dual_arm_description/meshes/revo2_left_hand/left_middle_touch_link.STL" />
      </geometry>
    </collision>
  </link>
  <joint name="left_middle_touch_joint" type="fixed">
    <origin xyz="0.012493 0 0.028393" rpy="0 0.34907 0" />
    <parent link="left_middle_distal_link" />
    <child link="left_middle_touch_link" />
    <axis xyz="0 0 0" />
  </joint>
  <link name="left_ring_proximal_link">
    <inertial>
      <origin xyz="-0.00234461360118865 -5.32058096490429E-06 0.0191785931520923" rpy="0 0 0" />
      <mass value="0.009" />
      <inertia ixx="3.14182210853629E-07" ixy="-3.44825864493725E-11" ixz="-7.78011903077364E-09" iyy="2.97623388067888E-07" iyz="-2.45023710126397E-10" izz="1.02120946203075E-07" />
    </inertial>
    <visual>
      <origin xyz="0 0 0" rpy="0 0 0" />
      <geometry>
        <mesh filename="package://taihu_dual_arm_description/meshes/revo2_left_hand/left_ring_proximal_link.STL" />
      </geometry>
      <material name="">
        <color rgba="1 1 1 1" />
      </material>
    </visual>
    <collision>
      <origin xyz="0 0 0" rpy="0 0 0" />
      <geometry>
        <mesh filename="package://taihu_dual_arm_description/meshes/revo2_left_hand/left_ring_proximal_link.STL" />
      </geometry>
    </collision>
  </link>
  <joint name="left_ring_proximal_joint" type="revolute">
    <origin xyz="-0.0046877 0.010026 0.083982" rpy="-0.039462 0.14721 -0.057932" />
    <parent link="left_hand_base_link" />
    <child link="left_ring_proximal_link" />
    <axis xyz="0 1 0" />
    <limit lower="0" upper="1.41" effort="2" velocity="2.2685" />
  </joint>
  <link name="left_ring_distal_link">
    <inertial>
      <origin xyz="0.00177053636256925 6.44490570182732E-08 0.0163889588075686" rpy="0 0 0" />
      <mass value="0.009" />
      <inertia ixx="4.97910632685663E-07" ixy="-7.13155362656436E-13" ixz="-7.8333106177264E-08" iyy="5.06076323023651E-07" iyz="-3.12724415128725E-12" izz="8.96496585961614E-08" />
    </inertial>
    <visual>
      <origin xyz="0 0 0" rpy="0 0 0" />
      <geometry>
        <mesh filename="package://taihu_dual_arm_description/meshes/revo2_left_hand/left_ring_distal_link.STL" />
      </geometry>
      <material name="">
        <color rgba="1 1 1 1" />
      </material>
    </visual>
    <collision>
      <origin xyz="0 0 0" rpy="0 0 0" />
      <geometry>
        <mesh filename="package://taihu_dual_arm_description/meshes/revo2_left_hand/left_ring_distal_link.STL" />
      </geometry>
    </collision>
  </link>
  <joint name="left_ring_distal_joint" type="revolute">
    <origin xyz="0 0 0.035" rpy="0 0.12654 0" />
    <parent link="left_ring_proximal_link" />
    <child link="left_ring_distal_link" />
    <axis xyz="0 1 0" />
    <limit lower="0" upper="1.63" effort="2" velocity="2.2685" />
    <mimic joint="left_ring_proximal_joint" multiplier="1.155" offset="0" />
  </joint>
  <link name="left_ring_tip_link">
  </link>
  <joint name="left_ring_tip_joint" type="fixed">
    <origin xyz="0.0071824 0 0.040734" rpy="0 0.34907 0" />
    <parent link="left_ring_distal_link" />
    <child link="left_ring_tip_link" />
    <axis xyz="0 0 0" />
  </joint>
  <link name="left_ring_touch_link">
    <inertial>
      <origin xyz="-0.00302345977584328 -4.05745081005771E-08 0.00304075994548066" rpy="0 0 0" />
      <mass value="0.002" />
      <inertia ixx="8.20180397723655E-09" ixy="-4.46948642471342E-14" ixz="1.83211397314813E-09" iyy="6.6365125312521E-09" iyz="5.98352266349244E-14" izz="3.6192579315874E-09" />
    </inertial>
    <visual>
      <origin xyz="0 0 0" rpy="0 0 0" />
      <geometry>
        <mesh filename="package://taihu_dual_arm_description/meshes/revo2_left_hand/left_ring_touch_link.STL" />
      </geometry>
      <material name="">
        <color rgba="1 1 1 1" />
      </material>
    </visual>
    <collision>
      <origin xyz="0 0 0" rpy="0 0 0" />
      <geometry>
        <mesh filename="package://taihu_dual_arm_description/meshes/revo2_left_hand/left_ring_touch_link.STL" />
      </geometry>
    </collision>
  </link>
  <joint name="left_ring_touch_joint" type="fixed">
    <origin xyz="0.012028 0 0.027796" rpy="0 0.34907 0" />
    <parent link="left_ring_distal_link" />
    <child link="left_ring_touch_link" />
    <axis xyz="0 0 0" />
  </joint>
  <link name="left_pinky_proximal_link">
    <inertial>
      <origin xyz="-0.00213266608574047 -7.02260316783054E-06 0.0160680350593264" rpy="0 0 0" />
      <mass value="0.009" />
      <inertia ixx="1.97554078210582E-07" ixy="-1.34133676966674E-11" ixz="-4.58601823842206E-09" iyy="1.82022483454667E-07" iyz="-1.01838144940486E-10" izz="8.21758160050774E-08" />
    </inertial>
    <visual>
      <origin xyz="0 0 0" rpy="0 0 0" />
      <geometry>
        <mesh filename="package://taihu_dual_arm_description/meshes/revo2_left_hand/left_pinky_proximal_link.STL" />
      </geometry>
      <material name="">
        <color rgba="1 1 1 1" />
      </material>
    </visual>
    <collision>
      <origin xyz="0 0 0" rpy="0 0 0" />
      <geometry>
        <mesh filename="package://taihu_dual_arm_description/meshes/revo2_left_hand/left_pinky_proximal_link.STL" />
      </geometry>
    </collision>
  </link>
  <joint name="left_pinky_proximal_joint" type="revolute">
    <origin xyz="-0.0023733 0.029356 0.078694" rpy="-0.11815 0.14491 -0.17392" />
    <parent link="left_hand_base_link" />
    <child link="left_pinky_proximal_link" />
    <axis xyz="0 1 0" />
    <limit lower="0" upper="1.41" effort="2" velocity="2.2685" />
  </joint>
  <link name="left_pinky_distal_link">
    <inertial>
      <origin xyz="0.00307951040509596 -1.22880919793678E-07 0.0130238921688021" rpy="0 0 0" />
      <mass value="0.009" />
      <inertia ixx="2.70011721564217E-07" ixy="-3.87297641763705E-13" ixz="-6.70652466728246E-08" iyy="2.85232998853131E-07" iyz="2.31120225284722E-12" izz="7.90738051832137E-08" />
    </inertial>
    <visual>
      <origin xyz="0 0 0" rpy="0 0 0" />
      <geometry>
        <mesh filename="package://taihu_dual_arm_description/meshes/revo2_left_hand/left_pinky_distal_link.STL" />
      </geometry>
      <material name="">
        <color rgba="1 1 1 1" />
      </material>
    </visual>
    <collision>
      <origin xyz="0 0 0" rpy="0 0 0" />
      <geometry>
        <mesh filename="package://taihu_dual_arm_description/meshes/revo2_left_hand/left_pinky_distal_link.STL" />
      </geometry>
    </collision>
  </link>
  <joint name="left_pinky_distal_joint" type="revolute">
    <origin xyz="0 0 0.029" rpy="0 0 0" />
    <parent link="left_pinky_proximal_link" />
    <child link="left_pinky_distal_link" />
    <axis xyz="0 1 0" />
    <limit lower="0" upper="1.63" effort="2" velocity="2.2685" />
    <mimic joint="left_pinky_proximal_joint" multiplier="1.155" offset="0" />
  </joint>
  <link name="left_pinky_tip_link">
  </link>
  <joint name="left_pinky_tip_joint" type="fixed">
    <origin xyz="0.010221 0 0.032918" rpy="0 0.4756 0" />
    <parent link="left_pinky_distal_link" />
    <child link="left_pinky_tip_link" />
    <axis xyz="0 0 0" />
  </joint>
  <link name="left_pinky_touch_link">
    <inertial>
      <origin xyz="-0.00289141700902749 -2.11561558237372E-07 0.00165388079364141" rpy="0 0 0" />
      <mass value="0.002" />
      <inertia ixx="6.9191441933911E-09" ixy="1.05433982553728E-13" ixz="1.42746467369115E-09" iyy="5.34360711670272E-09" iyz="-7.73258724722553E-14" izz="3.28292125954561E-09" />
    </inertial>
    <visual>
      <origin xyz="0 0 0" rpy="0 0 0" />
      <geometry>
        <mesh filename="package://taihu_dual_arm_description/meshes/revo2_left_hand/left_pinky_touch_link.STL" />
      </geometry>
      <material name="">
        <color rgba="1 1 1 1" />
      </material>
    </visual>
    <collision>
      <origin xyz="0 0 0" rpy="0 0 0" />
      <geometry>
        <mesh filename="package://taihu_dual_arm_description/meshes/revo2_left_hand/left_pinky_touch_link.STL" />
      </geometry>
    </collision>
  </link>
  <joint name="left_pinky_touch_joint" type="fixed">
    <origin xyz="0.01401 0 0.021124" rpy="0 0.4756 0" />
    <parent link="left_pinky_distal_link" />
    <child link="left_pinky_touch_link" />
    <axis xyz="0 0 0" />
  </joint>

  <!-- right hand -->
  <link name="right_hand_base_link">
    <inertial>
      <origin xyz="-0.0052437813922142 -0.00340380255263376 0.0521266765719498" rpy="0 0 0" />
      <mass value="0.238" />
      <inertia ixx="2.10911666669912E-05" ixy="3.86322047662032E-08" ixz="9.36399145709391E-08" iyy="1.44621914759073E-05" iyz="-1.09576502000447E-06" izz="7.99811499549963E-06" />
    </inertial>
    <visual>
      <origin xyz="0 0 0" rpy="0 0 0" />
      <geometry>
        <mesh filename="package://taihu_dual_arm_description/meshes/revo2_right_hand/right_base_link.STL" />
      </geometry>
      <material name="">
        <color rgba="1 1 1 1" />
      </material>
    </visual>
    <visual>
      <origin xyz="0 0 0" rpy="0 0 0" />
      <geometry>
        <mesh filename="package://taihu_dual_arm_description/meshes/revo2_right_hand/right_base_visual_link.STL" />
      </geometry>
      <material name="">
        <color rgba="1 1 1 1" />
      </material>
    </visual>
    <collision>
      <origin xyz="0 0 0" rpy="0 0 0" />
      <geometry>
        <mesh filename="package://taihu_dual_arm_description/meshes/revo2_right_hand/right_base_link.STL" />
      </geometry>
    </collision>
  </link>
  <joint name="right_hand_base_joint" type="fixed">
    <origin xyz="0 0 0" rpy="1.5707963 1.5707963 0" />
    <parent link="R_HAND_S" />
    <child link="right_hand_base_link" />
    <axis xyz="0 0 0" />
  </joint>
  <link name="right_thumb_metacarpal_link">
    <inertial>
      <origin xyz="1.51105893291953E-05 0.00707242532016975 -0.00420847293427094" rpy="0 0 0" />
      <mass value="0.01" />
      <inertia ixx="1.59239837111329E-07" ixy="-4.69100836631313E-09" ixz="4.92933775261579E-10" iyy="1.60913456568321E-07" iyz="-1.48146725871811E-08" izz="5.13550255314669E-08" />
    </inertial>
    <visual>
      <origin xyz="0 0 0" rpy="0 0 0" />
      <geometry>
        <mesh filename="package://taihu_dual_arm_description/meshes/revo2_right_hand/right_thumb_metacarpal_link.STL" />
      </geometry>
      <material name="">
        <color rgba="1 1 1 1" />
      </material>
    </visual>
    <collision>
      <origin xyz="0 0 0" rpy="0 0 0" />
      <geometry>
        <mesh filename="package://taihu_dual_arm_description/meshes/revo2_right_hand/right_thumb_metacarpal_link.STL" />
      </geometry>
    </collision>
  </link>
  <joint name="right_thumb_metacarpal_joint" type="revolute">
    <origin xyz="0.005619 0.019867 0.027825" rpy="0 0 -0.16787" />
    <parent link="right_hand_base_link" />
    <child link="right_thumb_metacarpal_link" />
    <axis xyz="0 0 -1" />
    <limit lower="0" upper="1.57" effort="0.5" velocity="2.6175" />
  </joint>
  <link name="right_thumb_proximal_link">
    <inertial>
      <origin xyz="-4.69719500198473E-07 0.0277015013193164 -0.00202656319478134" rpy="0 0 0" />
      <mass value="0.05" />
      <inertia ixx="2.40451952538979E-06" ixy="-1.31092767621418E-10" ixz="8.32477243895752E-12" iyy="5.12323837647516E-07" iyz="-2.89154745634785E-08" izz="2.56254219597565E-06" />
    </inertial>
    <visual>
      <origin xyz="0 0 0" rpy="0 0 0" />
      <geometry>
        <mesh filename="package://taihu_dual_arm_description/meshes/revo2_right_hand/right_thumb_proximal_visual_link.STL" />
      </geometry>
      <material name="">
        <color rgba="1 1 1 1" />
      </material>
    </visual>
    <collision>
      <origin xyz="0 0 0" rpy="0 0 0" />
      <geometry>
        <mesh filename="package://taihu_dual_arm_description/meshes/revo2_right_hand/right_thumb_proximal_link.STL" />
      </geometry>
    </collision>
  </link>
  <joint name="right_thumb_proximal_joint" type="revolute">
    <origin xyz="0 0.014227 0" rpy="0.17488 0.23736 0.16787" />
    <parent link="right_thumb_metacarpal_link" />
    <child link="right_thumb_proximal_link" />
    <axis xyz="1 0 0" />
    <limit lower="0" upper="1.03" effort="1.1" velocity="2.5303" />
  </joint>
  <link name="right_thumb_distal_link">
    <inertial>
      <origin xyz="-5.88258312894663E-09 0.0117544716247141 1.13324397438934E-05" rpy="0 0 0" />
      <mass value="0.01" />
      <inertia ixx="1.67793545309794E-07" ixy="7.1592784782531E-12" ixz="-6.80095370887263E-12" iyy="1.15362128819332E-07" iyz="1.2517499089377E-08" izz="2.19553178338424E-07" />
    </inertial>
    <visual>
      <origin xyz="0 0 0" rpy="0 0 0" />
      <geometry>
        <mesh filename="package://taihu_dual_arm_description/meshes/revo2_right_hand/right_thumb_distal_link.STL" />
      </geometry>
      <material name="">
        <color rgba="1 1 1 1" />
      </material>
    </visual>
    <collision>
      <origin xyz="0 0 0" rpy="0 0 0" />
      <geometry>
        <mesh filename="package://taihu_dual_arm_description/meshes/revo2_right_hand/right_thumb_distal_link.STL" />
      </geometry>
    </collision>
  </link>
  <joint name="right_thumb_distal_joint" type="revolute">
    <origin xyz="0 0.052 0" rpy="0 0 0" />
    <parent link="right_thumb_proximal_link" />
    <child link="right_thumb_distal_link" />
    <axis xyz="1 0 0" />
    <limit lower="0" upper="1.03" effort="1.1" velocity="2.5303" />
    <mimic joint="right_thumb_proximal_joint" multiplier="1" offset="0" />
  </joint>
  <link name="right_thumb_tip_link">
  </link>
  <joint name="right_thumb_tip_joint" type="fixed">
    <origin xyz="0 0.0265287811635831 -0.00177344281307929" rpy="-0.0667504507189062 0 0" />
    <parent link="right_thumb_distal_link" />
    <child link="right_thumb_tip_link" />
    <axis xyz="0 0 0" />
  </joint>
  <link name="right_thumb_touch_link">
    <inertial>
      <origin xyz="-1.1806027010175E-08 -0.00152252748962305 -0.00778417824955365" rpy="0 0 0" />
      <mass value="0.002" />
      <inertia ixx="1.67793545299225E-07" ixy="7.5594784738105E-12" ixz="-6.38541374289843E-12" iyy="1.14159537766499E-07" iyz="5.47195888787862E-09" izz="2.20755769355424E-07" />
    </inertial>
    <visual>
      <origin xyz="0 0 0" rpy="0 0 0" />
      <geometry>
        <mesh filename="package://taihu_dual_arm_description/meshes/revo2_right_hand/right_thumb_touch_link.STL" />
      </geometry>
      <material name="">
        <color rgba="1 1 1 1" />
      </material>
    </visual>
    <collision>
      <origin xyz="0 0 0" rpy="0 0 0" />
      <geometry>
        <mesh filename="package://taihu_dual_arm_description/meshes/revo2_right_hand/right_thumb_touch_link.STL" />
      </geometry>
    </collision>
  </link>
  <joint name="right_thumb_touch_joint" type="fixed">
    <origin xyz="0 0.0137927522748974 0.00767659940411662" rpy="-0.0667504507189062 0 0" />
    <parent link="right_thumb_distal_link" />
    <child link="right_thumb_touch_link" />
    <axis xyz="0 0 0" />
  </joint>
  <link name="right_index_proximal_link">
    <inertial>
      <origin xyz="-0.00223495193199565 3.15874577787312E-06 0.0176402020341366" rpy="0 0 0" />
      <mass value="0.009" />
      <inertia ixx="2.51945688372283E-07" ixy="1.19772964297278E-11" ixz="-6.37275644668917E-09" iyy="2.36435336139899E-07" iyz="1.65019165740599E-10" izz="9.30351046594029E-08" />
    </inertial>
    <visual>
      <origin xyz="0 0 0" rpy="0 0 0" />
      <geometry>
        <mesh filename="package://taihu_dual_arm_description/meshes/revo2_right_hand/right_index_proximal_link.STL" />
      </geometry>
      <material name="">
        <color rgba="1 1 1 1" />
      </material>
    </visual>
    <collision>
      <origin xyz="0 0 0" rpy="0 0 0" />
      <geometry>
        <mesh filename="package://taihu_dual_arm_description/meshes/revo2_right_hand/right_index_proximal_link.STL" />
      </geometry>
    </collision>
  </link>
  <joint name="right_index_proximal_joint" type="revolute">
    <origin xyz="-0.0021181 0.029568 0.080876" rpy="-0.11819 0.14743 -0.17422" />
    <parent link="right_hand_base_link" />
    <child link="right_index_proximal_link" />
    <axis xyz="0 1 0" />
    <limit lower="0" upper="1.41" effort="2" velocity="2.2685" />
  </joint>
  <link name="right_index_distal_link">
    <inertial>
      <origin xyz="0.00330169965345207 1.80502678033545E-07 0.0142076903844267" rpy="0 0 0" />
      <mass value="0.009" />
      <inertia ixx="3.39968050760851E-07" ixy="-2.72439842925177E-12" ixz="-8.75041192697868E-08" iyy="3.62244794159632E-07" iyz="-3.69168934117452E-12" izz="9.1034511229316E-08" />
    </inertial>
    <visual>
      <origin xyz="0 0 0" rpy="0 0 0" />
      <geometry>
        <mesh filename="package://taihu_dual_arm_description/meshes/revo2_right_hand/right_index_distal_link.STL" />
      </geometry>
      <material name="">
        <color rgba="1 1 1 1" />
      </material>
    </visual>
    <collision>
      <origin xyz="0 0 0" rpy="0 0 0" />
      <geometry>
        <mesh filename="package://taihu_dual_arm_description/meshes/revo2_right_hand/right_index_distal_link.STL" />
      </geometry>
    </collision>
  </link>
  <joint name="right_index_distal_joint" type="revolute">
    <origin xyz="0 0 0.032" rpy="0 0 0" />
    <parent link="right_index_proximal_link" />
    <child link="right_index_distal_link" />
    <axis xyz="0 1 0" />
    <limit lower="0" upper="1.63" effort="2" velocity="2.2685" />
    <mimic joint="right_index_proximal_joint" multiplier="1.155" offset="0" />
  </joint>
  <link name="right_index_tip_link">
  </link>
  <joint name="right_index_tip_joint" type="fixed">
    <origin xyz="0.011097 0 0.035739" rpy="0 0.4756 0" />
    <parent link="right_index_distal_link" />
    <child link="right_index_tip_link" />
    <axis xyz="0 0 0" />
  </joint>
  <link name="right_index_touch_link">
    <inertial>
      <origin xyz="-0.00299911641156304 0.00249742609184543 -0.000361457745670764" rpy="0 0 0" />
      <mass value="0.002" />
      <inertia ixx="6.77691690725075E-09" ixy="1.49925053858217E-09" ixz="-2.16894115716066E-10" iyy="3.23801290825914E-09" iyz="3.14646833837905E-10" izz="5.36791538949697E-09" />
    </inertial>
    <visual>
      <origin xyz="0 0 0" rpy="0 0 0" />
      <geometry>
        <mesh filename="package://taihu_dual_arm_description/meshes/revo2_right_hand/right_index_touch_link.STL" />
      </geometry>
      <material name="">
        <color rgba="1 1 1 1" />
      </material>
    </visual>
    <collision>
      <origin xyz="0 0 0" rpy="0 0 0" />
      <geometry>
        <mesh filename="package://taihu_dual_arm_description/meshes/revo2_right_hand/right_index_touch_link.STL" />
      </geometry>
    </collision>
  </link>
  <joint name="right_index_touch_joint" type="fixed">
    <origin xyz="0.014497 0 0.023303" rpy="1.7145 0.4756 0" />
    <parent link="right_index_distal_link" />
    <child link="right_index_touch_link" />
    <axis xyz="0 0 0" />
  </joint>
  <link name="right_middle_proximal_link">
    <inertial>
      <origin xyz="-0.00222511101223747 5.25632286623237E-06 0.0203007776295123" rpy="0 0 0" />
      <mass value="0.009" />
      <inertia ixx="3.6699623719538E-07" ixy="2.68340899395639E-11" ixz="-9.79836587937102E-09" iyy="3.52645347928613E-07" iyz="2.5786558273981E-10" izz="1.12233932527467E-07" />
    </inertial>
    <visual>
      <origin xyz="0 0 0" rpy="0 0 0" />
      <geometry>
        <mesh filename="package://taihu_dual_arm_description/meshes/revo2_right_hand/right_middle_proximal_link.STL" />
      </geometry>
      <material name="">
        <color rgba="1 1 1 1" />
      </material>
    </visual>
    <collision>
      <origin xyz="0 0 0" rpy="0 0 0" />
      <geometry>
        <mesh filename="package://taihu_dual_arm_description/meshes/revo2_right_hand/right_middle_proximal_link.STL" />
      </geometry>
    </collision>
  </link>
  <joint name="right_middle_proximal_joint" type="revolute">
    <origin xyz="-0.0045767 0.010051 0.084993" rpy="-0.039468 0.1483 -0.057975" />
    <parent link="right_hand_base_link" />
    <child link="right_middle_proximal_link" />
    <axis xyz="0 1 0" />
    <limit lower="0" upper="1.41" effort="2" velocity="2.2685" />
  </joint>
  <link name="right_middle_distal_link">
    <inertial>
      <origin xyz="0.00400815246049972 -2.93852058033672E-08 0.0164973984498919" rpy="0 0 0" />
      <mass value="0.009" />
      <inertia ixx="5.12550471641205E-07" ixy="2.4957446124327E-12" ixz="-1.36569370373267E-07" iyy="5.4982769389762E-07" iyz="1.1510593712868E-12" izz="1.23560211132881E-07" />
    </inertial>
    <visual>
      <origin xyz="0 0 0" rpy="0 0 0" />
      <geometry>
        <mesh filename="package://taihu_dual_arm_description/meshes/revo2_right_hand/right_middle_distal_link.STL" />
      </geometry>
      <material name="">
        <color rgba="1 1 1 1" />
      </material>
    </visual>
    <collision>
      <origin xyz="0 0 0" rpy="0 0 0" />
      <geometry>
        <mesh filename="package://taihu_dual_arm_description/meshes/revo2_right_hand/right_middle_distal_link.STL" />
      </geometry>
    </collision>
  </link>
  <joint name="right_middle_distal_joint" type="revolute">
    <origin xyz="0 0 0.037" rpy="0 0 0" />
    <parent link="right_middle_proximal_link" />
    <child link="right_middle_distal_link" />
    <axis xyz="0 1 0" />
    <limit lower="0" upper="1.63" effort="2" velocity="2.2685" />
    <mimic joint="right_middle_proximal_joint" multiplier="1.155" offset="0" />
  </joint>
  <link name="right_middle_tip_link">
  </link>
  <joint name="right_middle_tip_joint" type="fixed">
    <origin xyz="0.012558 0 0.040442" rpy="0 0.4756 0" />
    <parent link="right_middle_distal_link" />
    <child link="right_middle_tip_link" />
    <axis xyz="0 0 0" />
  </joint>
  <link name="right_middle_touch_link">
    <inertial>
      <origin xyz="-0.00319289171453651 -1.92251098651841E-08 0.00297860354010647" rpy="0 0 0" />
      <mass value="0.002" />
      <inertia ixx="1.00486658585813E-08" ixy="-7.87051809312931E-14" ixz="2.25917784171234E-09" iyy="8.23228109049258E-09" iyz="1.50825328552765E-13" izz="4.41272192206512E-09" />
    </inertial>
    <visual>
      <origin xyz="0 0 0" rpy="0 0 0" />
      <geometry>
        <mesh filename="package://taihu_dual_arm_description/meshes/revo2_right_hand/right_middle_touch_link.STL" />
      </geometry>
      <material name="">
        <color rgba="1 1 1 1" />
      </material>
    </visual>
    <collision>
      <origin xyz="0 0 0" rpy="0 0 0" />
      <geometry>
        <mesh filename="package://taihu_dual_arm_description/meshes/revo2_right_hand/right_middle_touch_link.STL" />
      </geometry>
    </collision>
  </link>
  <joint name="right_middle_touch_joint" type="fixed">
    <origin xyz="0.015975871997898 0 0.0265894268903603" rpy="0 0.475602221168456 0" />
    <parent link="right_middle_distal_link" />
    <child link="right_middle_touch_link" />
    <axis xyz="0 0 0" />
  </joint>
  <link name="right_ring_proximal_link">
    <inertial>
      <origin xyz="-0.00234494526421452 5.87954755621161E-06 0.019177402549597" rpy="0 0 0" />
      <mass value="0.009" />
      <inertia ixx="3.14177684848335E-07" ixy="3.34382331089976E-11" ixz="-7.78981780892183E-09" iyy="2.97613170150896E-07" iyz="2.41251871804457E-10" izz="1.0211543233675E-07" />
    </inertial>
    <visual>
      <origin xyz="0 0 0" rpy="0 0 0" />
      <geometry>
        <mesh filename="package://taihu_dual_arm_description/meshes/revo2_right_hand/right_ring_proximal_link.STL" />
      </geometry>
      <material name="">
        <color rgba="1 1 1 1" />
      </material>
    </visual>
    <collision>
      <origin xyz="0 0 0" rpy="0 0 0" />
      <geometry>
        <mesh filename="package://taihu_dual_arm_description/meshes/revo2_right_hand/right_ring_proximal_link.STL" />
      </geometry>
    </collision>
  </link>
  <joint name="right_ring_proximal_joint" type="revolute">
    <origin xyz="-0.0046709 -0.010037 0.083982" rpy="0.039462 0.14721 0.057932" />
    <parent link="right_hand_base_link" />
    <child link="right_ring_proximal_link" />
    <axis xyz="0 1 0" />
    <limit lower="0" upper="1.41" effort="2" velocity="2.2685" />
  </joint>
  <link name="right_ring_distal_link">
    <inertial>
      <origin xyz="0.00382459959210406 7.8017874437751E-08 0.0160343764410312" rpy="0 0 0" />
      <mass value="0.009" />
      <inertia ixx="4.71792497420504E-07" ixy="-6.95225674723301E-13" ixz="-1.26948440940938E-07" iyy="5.06071998616974E-07" iyz="-2.19413968646526E-12" izz="1.15762768100302E-07" />
    </inertial>
    <visual>
      <origin xyz="0 0 0" rpy="0 0 0" />
      <geometry>
        <mesh filename="package://taihu_dual_arm_description/meshes/revo2_right_hand/right_ring_distal_link.STL" />
      </geometry>
      <material name="">
        <color rgba="1 1 1 1" />
      </material>
    </visual>
    <collision>
      <origin xyz="0 0 0" rpy="0 0 0" />
      <geometry>
        <mesh filename="package://taihu_dual_arm_description/meshes/revo2_right_hand/right_ring_distal_link.STL" />
      </geometry>
    </collision>
  </link>
  <joint name="right_ring_distal_joint" type="revolute">
    <origin xyz="0 0 0.035" rpy="0 0 0" />
    <parent link="right_ring_proximal_link" />
    <child link="right_ring_distal_link" />
    <axis xyz="0 1 0" />
    <limit lower="0" upper="1.63" effort="2" velocity="2.2685" />
    <mimic joint="right_ring_proximal_joint" multiplier="1.155" offset="0" />
  </joint>
  <link name="right_ring_tip_link">
  </link>
  <joint name="right_ring_tip_joint" type="fixed">
    <origin xyz="0.012266 0 0.039501" rpy="0 0.4756 0" />
    <parent link="right_ring_distal_link" />
    <child link="right_ring_tip_link" />
    <axis xyz="0 0 0" />
  </joint>
  <link name="right_ring_touch_link">
    <inertial>
      <origin xyz="-0.00302345770059939 -4.42584829375703E-08 0.0030407600788087" rpy="0 0 0" />
      <mass value="0.002" />
      <inertia ixx="8.20180993934663E-09" ixy="-2.63295949836146E-14" ixz="1.83211342144402E-09" iyy="6.63652036961065E-09" iyz="1.12534283673606E-13" izz="3.61925974724395E-09" />
    </inertial>
    <visual>
      <origin xyz="0 0 0" rpy="0 0 0" />
      <geometry>
        <mesh filename="package://taihu_dual_arm_description/meshes/revo2_right_hand/right_ring_touch_link.STL" />
      </geometry>
      <material name="">
        <color rgba="1 1 1 1" />
      </material>
    </visual>
    <collision>
      <origin xyz="0 0 0" rpy="0 0 0" />
      <geometry>
        <mesh filename="package://taihu_dual_arm_description/meshes/revo2_right_hand/right_ring_touch_link.STL" />
      </geometry>
    </collision>
  </link>
  <joint name="right_ring_touch_joint" type="fixed">
    <origin xyz="0.0154392324697935 0 0.0260561041381566" rpy="0 0.475602221168648 0" />
    <parent link="right_ring_distal_link" />
    <child link="right_ring_touch_link" />
    <axis xyz="0 0 0" />
  </joint>
  <link name="right_pinky_proximal_link">
    <inertial>
      <origin xyz="-0.00213212021184178 7.75039446098032E-06 0.0160671583560383" rpy="0 0 0" />
      <mass value="0.009" />
      <inertia ixx="1.97563213550085E-07" ixy="2.23402433057963E-11" ixz="-4.58425663692079E-09" iyy="1.82023043083307E-07" iyz="1.08028441152494E-10" izz="8.21624712033168E-08" />
    </inertial>
    <visual>
      <origin xyz="0 0 0" rpy="0 0 0" />
      <geometry>
        <mesh filename="package://taihu_dual_arm_description/meshes/revo2_right_hand/right_pinky_proximal_link.STL" />
      </geometry>
      <material name="">
        <color rgba="1 1 1 1" />
      </material>
    </visual>
    <collision>
      <origin xyz="0 0 0" rpy="0 0 0" />
      <geometry>
        <mesh filename="package://taihu_dual_arm_description/meshes/revo2_right_hand/right_pinky_proximal_link.STL" />
      </geometry>
    </collision>
  </link>
  <joint name="right_pinky_proximal_joint" type="revolute">
    <origin xyz="-0.0023566 -0.029366 0.078694" rpy="0.11815 0.14491 0.17392" />
    <parent link="right_hand_base_link" />
    <child link="right_pinky_proximal_link" />
    <axis xyz="0 1 0" />
    <limit lower="0" upper="1.41" effort="2" velocity="2.2685" />
  </joint>
  <link name="right_pinky_distal_link">
    <inertial>
      <origin xyz="0.00307974197235919 -1.54572112227858E-07 0.0130246967256256" rpy="0 0 0" />
      <mass value="0.009" />
      <inertia ixx="2.70050429038431E-07" ixy="1.68029751000565E-12" ixz="-6.70780254430148E-08" iyy="2.85275081521347E-07" iyz="5.10635117768255E-12" izz="7.90798706854226E-08" />
    </inertial>
    <visual>
      <origin xyz="0 0 0" rpy="0 0 0" />
      <geometry>
        <mesh filename="package://taihu_dual_arm_description/meshes/revo2_right_hand/right_pinky_distal_link.STL" />
      </geometry>
      <material name="">
        <color rgba="1 1 1 1" />
      </material>
    </visual>
    <collision>
      <origin xyz="0 0 0" rpy="0 0 0" />
      <geometry>
        <mesh filename="package://taihu_dual_arm_description/meshes/revo2_right_hand/right_pinky_distal_link.STL" />
      </geometry>
    </collision>
  </link>
  <joint name="right_pinky_distal_joint" type="revolute">
    <origin xyz="0 0 0.029" rpy="0 0 0" />
    <parent link="right_pinky_proximal_link" />
    <child link="right_pinky_distal_link" />
    <axis xyz="0 1 0" />
    <limit lower="0" upper="1.63" effort="2" velocity="2.2685" />
    <mimic joint="right_pinky_proximal_joint" multiplier="1.155" offset="0" />
  </joint>
  <link name="right_pinky_tip_link">
  </link>
  <joint name="right_pinky_tip_joint" type="fixed">
    <origin xyz="0.010221 0 0.032918" rpy="0 0.4756 0" />
    <parent link="right_pinky_distal_link" />
    <child link="right_pinky_tip_link" />
    <axis xyz="0 0 0" />
  </joint>
  <link name="right_pinky_touch_link">
    <inertial>
      <origin xyz="-0.00289142401155668 -2.00563398826403E-07 0.00165387959177493" rpy="0 0 0" />
      <mass value="0.002" />
      <inertia ixx="6.91911795672566E-09" ixy="1.21758056374209E-13" ixz="1.42748611971717E-09" iyy="5.34364749688619E-09" iyz="7.16346527443829E-14" izz="3.28289727389894E-09" />
    </inertial>
    <visual>
      <origin xyz="0 0 0" rpy="0 0 0" />
      <geometry>
        <mesh filename="package://taihu_dual_arm_description/meshes/revo2_right_hand/right_pinky_touch_link.STL" />
      </geometry>
      <material name="">
        <color rgba="1 1 1 1" />
      </material>
    </visual>
    <collision>
      <origin xyz="0 0 0" rpy="0 0 0" />
      <geometry>
        <mesh filename="package://taihu_dual_arm_description/meshes/revo2_right_hand/right_pinky_touch_link.STL" />
      </geometry>
    </collision>
  </link>
  <joint name="right_pinky_touch_joint" type="fixed">
    <origin xyz="0.01401 0 0.021124" rpy="0 0.4756 0" />
    <parent link="right_pinky_distal_link" />
    <child link="right_pinky_touch_link" />
    <axis xyz="0 0 0" />
  </joint>

</robot>
